Traceback (most recent call last):
  File "/mnt/data/miniconda3/lib/python3.13/site-packages/pydantic/networks.py", line 946, in import_email_validator
    import email_validator
ModuleNotFoundError: No module named 'email_validator'

The above exception was the direct cause of the following exception:

Traceback (most recent call last):
  File "/mnt/data/Pasia/Cliebt/Project/document-processor/main.py", line 10, in <module>
    from api.endpoints import router
  File "/mnt/data/Pasia/Cliebt/Project/document-processor/api/endpoints.py", line 30, in <module>
    from models.user import (
    ...<2 lines>...
    )
  File "/mnt/data/Pasia/Cliebt/Project/document-processor/models/user.py", line 23, in <module>
    class UserSignupRequest(BaseModel):
    ...<3 lines>...
        last_name: Optional[str] = None
  File "/mnt/data/miniconda3/lib/python3.13/site-packages/pydantic/_internal/_model_construction.py", line 237, in __new__
    complete_model_class(
    ~~~~~~~~~~~~~~~~~~~~^
        cls,
        ^^^^
    ...<3 lines>...
        create_model_module=_create_model_module,
        ^^^^^^^^^^^^^^^^^^^^^^^^^^^^^^^^^^^^^^^^^
    )
    ^
  File "/mnt/data/miniconda3/lib/python3.13/site-packages/pydantic/_internal/_model_construction.py", line 597, in complete_model_class
    schema = gen_schema.generate_schema(cls)
  File "/mnt/data/miniconda3/lib/python3.13/site-packages/pydantic/_internal/_generate_schema.py", line 711, in generate_schema
    schema = self._generate_schema_inner(obj)
  File "/mnt/data/miniconda3/lib/python3.13/site-packages/pydantic/_internal/_generate_schema.py", line 1004, in _generate_schema_inner
    return self._model_schema(obj)
           ~~~~~~~~~~~~~~~~~~^^^^^
  File "/mnt/data/miniconda3/lib/python3.13/site-packages/pydantic/_internal/_generate_schema.py", line 837, in _model_schema
    {k: self._generate_md_field_schema(k, v, decorators) for k, v in fields.items()},
        ~~~~~~~~~~~~~~~~~~~~~~~~~~~~~~^^^^^^^^^^^^^^^^^^
  File "/mnt/data/miniconda3/lib/python3.13/site-packages/pydantic/_internal/_generate_schema.py", line 1206, in _generate_md_field_schema
    common_field = self._common_field_schema(name, field_info, decorators)
  File "/mnt/data/miniconda3/lib/python3.13/site-packages/pydantic/_internal/_generate_schema.py", line 1372, in _common_field_schema
    schema = self._apply_annotations(
        source_type,
        annotations + validators_from_decorators,
    )
  File "/mnt/data/miniconda3/lib/python3.13/site-packages/pydantic/_internal/_generate_schema.py", line 2297, in _apply_annotations
    schema = get_inner_schema(source_type)
  File "/mnt/data/miniconda3/lib/python3.13/site-packages/pydantic/_internal/_schema_generation_shared.py", line 83, in __call__
    schema = self._handler(source_type)
  File "/mnt/data/miniconda3/lib/python3.13/site-packages/pydantic/_internal/_generate_schema.py", line 2276, in inner_handler
    schema = self._generate_schema_from_get_schema_method(obj, source_type)
  File "/mnt/data/miniconda3/lib/python3.13/site-packages/pydantic/_internal/_generate_schema.py", line 900, in _generate_schema_from_get_schema_method
    schema = get_schema(
        source, CallbackGetCoreSchemaHandler(self._generate_schema_inner, self, ref_mode=ref_mode)
    )
  File "/mnt/data/miniconda3/lib/python3.13/site-packages/pydantic/networks.py", line 986, in __get_pydantic_core_schema__
    import_email_validator()
    ~~~~~~~~~~~~~~~~~~~~~~^^
  File "/mnt/data/miniconda3/lib/python3.13/site-packages/pydantic/networks.py", line 948, in import_email_validator
    raise ImportError('email-validator is not installed, run `pip install pydantic[email]`') from e
ImportError: email-validator is not installed, run `pip install pydantic[email]`
